Workbook

Sheet Data Summary
C1: VMFRIENDS Parameters | I1: FRIENDS Measurements | O1: Vape Info.
B2: Vape | C2: Number of Puffs | D2: Puff Time (s) | E2: Total Puff Time (s) | F2: Interpuff Time (s) | G2: Puff Volume (mL) | H2: Puff Flow Rate (mL/s) | I2: Puffs Counted | J2: Puff Count RE (puff-weighted) | K2: Puff Count RE ± 95% CI (ratio estimator) | L2: Total Puff Time (s) | M2: Puff Time RE (puff-time-weighted) | N2: Puff Time RE ± 95% CI (ratio estimator) | O2: Thermistor Used (Y/N) | P2: Thermistor Needed (Y/N) | Q2: Characteristics | U2: n (sessions) | V2: Σ Delivered Puffs | W2: Σ Delivered Puff Time (s)
A3: 1 | B3: Adjust Myflavor | C3: 440 | D3: 3 | E3: =C3*D3 -> 1320 | F3: 18 | G3: 120 | H3: 40 | I3: 440 | J3: =SUMPRODUCT(ABS('All Data'!J64:J74-'All Data'!D64:D74))/$V3 -> 0 | K3: =IF($U3<2,"N/A (n=1)",TINV(0.05,$U3-1)*SQRT($U3*SUMPRODUCT((ABS('All Data'!J64:J74-'All Data'!D64:D74)-$J3*'All Data'!D64:D74)^2)/(($U3-1)*$V3^2))) -> 0 | L3: 1437.6144 | M3: =SUMPRODUCT(ABS('All Data'!K64:K74-'All Data'!F64:F74))/$W3 -> 0.089101818 | N3: =IF($U3<2,"N/A (n=1)",TINV(0.05,$U3-1)*SQRT($U3*SUMPRODUCT((ABS('All Data'!K64:K74-'All Data'!F64:F74)-$M3*'All Data'!F64:F74)^2)/(($U3-1)*$W3^2))) -> 0.0055238047 | O3: Y | P3: N | Q3: Closed System; Rechargeable | U3: =COUNT('All Data'!D64:D74) -> 11 | V3: =SUM('All Data'!D64:D74) -> 440 | W3: =SUM('All Data'!F64:F74) -> 1320
A4: 2 | B4: Artery CL6 | C4: 433 | D4: 3 | E4: =C4*D4 -> 1299 | F4: 18 | G4: 120 | H4: 40 | I4: 403 | J4: =SUMPRODUCT(ABS('All Data'!J76:J82-'All Data'!D76:D82))/$V4 -> 0.069284065 | K4: =IF($U4<2,"N/A (n=1)",TINV(0.05,$U4-1)*SQRT($U4*SUMPRODUCT((ABS('All Data'!J76:J82-'All Data'!D76:D82)-$J4*'All Data'!D76:D82)^2)/(($U4-1)*$V4^2))) -> 0.099512295 | L4: 1311.6472 | M4: =SUMPRODUCT(ABS('All Data'!K76:K82-'All Data'!F76:F82))/$W4 -> 0.091963048 | N4: =IF($U4<2,"N/A (n=1)",TINV(0.05,$U4-1)*SQRT($U4*SUMPRODUCT((ABS('All Data'!K76:K82-'All Data'!F76:F82)-$M4*'All Data'!F76:F82)^2)/(($U4-1)*$W4^2))) -> 0.10106322 | O4: Y | P4: N | Q4: Closed System; Rechargeable | U4: =COUNT('All Data'!D76:D82) -> 7 | V4: =SUM('All Data'!D76:D82) -> 433 | W4: =SUM('All Data'!F76:F82) -> 1299
A5: 3 | B5: Breeze Pro | C5: 400 | D5: 3 | E5: =C5*D5 -> 1200 | F5: 18 | G5: 120 | H5: 40 | I5: 397 | J5: =SUMPRODUCT(ABS('All Data'!J39:J43-'All Data'!D39:D43))/$V5 -> 0.0075 | K5: =IF($U5<2,"N/A (n=1)",TINV(0.05,$U5-1)*SQRT($U5*SUMPRODUCT((ABS('All Data'!J39:J43-'All Data'!D39:D43)-$J5*'All Data'!D39:D43)^2)/(($U5-1)*$V5^2))) -> 0.020823338 | L5: 1241.0303 | M5: =SUMPRODUCT(ABS('All Data'!K39:K43-'All Data'!F39:F43))/$W5 -> 0.034191917 | N5: =IF($U5<2,"N/A (n=1)",TINV(0.05,$U5-1)*SQRT($U5*SUMPRODUCT((ABS('All Data'!K39:K43-'All Data'!F39:F43)-$M5*'All Data'!F39:F43)^2)/(($U5-1)*$W5^2))) -> 0.013734479 | O5: Y | P5: Y | Q5: Closed System; Non-rechargeable | T5: ` | U5: =COUNT('All Data'!D39:D43) -> 5 | V5: =SUM('All Data'!D39:D43) -> 400 | W5: =SUM('All Data'!F39:F43) -> 1200
A6: 4 | B6: EBCreate BC 5000 | C6: 450 | D6: 3 | E6: =C6*D6 -> 1350 | F6: 18 | G6: 120 | H6: 40 | I6: 446 | J6: =SUMPRODUCT(ABS('All Data'!J84:J88-'All Data'!D84:D88))/$V6 -> 0.0088888889 | K6: =IF($U6<2,"N/A (n=1)",TINV(0.05,$U6-1)*SQRT($U6*SUMPRODUCT((ABS('All Data'!J84:J88-'All Data'!D84:D88)-$J6*'All Data'!D84:D88)^2)/(($U6-1)*$V6^2))) -> 0.013041524 | L6: 1358.2995 | M6: =SUMPRODUCT(ABS('All Data'!K84:K88-'All Data'!F84:F88))/$W6 -> 0.012941111 | N6: =IF($U6<2,"N/A (n=1)",TINV(0.05,$U6-1)*SQRT($U6*SUMPRODUCT((ABS('All Data'!K84:K88-'All Data'!F84:F88)-$M6*'All Data'!F84:F88)^2)/(($U6-1)*$W6^2))) -> 0.0080553114 | O6: Y | P6: Y | Q6: Closed System; Rechargeable | U6: =COUNT('All Data'!D84:D88) -> 5 | V6: =SUM('All Data'!D84:D88) -> 450 | W6: =SUM('All Data'!F84:F88) -> 1350
A7: 5 | B7: Elf Bar BC5000 | C7: 448 | D7: 3 | E7: 1344 | F7: 18 | G7: 120 | H7: 40 | I7: 448 | J7: =SUMPRODUCT(ABS('All Data'!J3:J8-'All Data'!D3:D8))/$V7 -> 0 | K7: =IF($U7<2,"N/A (n=1)",TINV(0.05,$U7-1)*SQRT($U7*SUMPRODUCT((ABS('All Data'!J3:J8-'All Data'!D3:D8)-$J7*'All Data'!D3:D8)^2)/(($U7-1)*$V7^2))) -> 0 | L7: 1380.2581 | M7: =SUMPRODUCT(ABS('All Data'!K3:K8-'All Data'!F3:F8))/$W7 -> 0.028843229 | N7: =IF($U7<2,"N/A (n=1)",TINV(0.05,$U7-1)*SQRT($U7*SUMPRODUCT((ABS('All Data'!K3:K8-'All Data'!F3:F8)-$M7*'All Data'!F3:F8)^2)/(($U7-1)*$W7^2))) -> 0.015849925 | O7: Y | P7: Y | Q7: Closed System; Rechargeable | U7: =COUNT('All Data'!D3:D8) -> 6 | V7: =SUM('All Data'!D3:D8) -> 448 | W7: =SUM('All Data'!F3:F8) -> 1344
A8: 6 | B8: Funky Republic ti7000 | C8: 560 | D8: 3 | E8: 1680 | F8: 18 | G8: 120 | H8: 40 | I8: 558 | J8: =SUMPRODUCT(ABS('All Data'!J31:J37-'All Data'!D31:D37))/$V8 -> 0.0071428571 | K8: =IF($U8<2,"N/A (n=1)",TINV(0.05,$U8-1)*SQRT($U8*SUMPRODUCT((ABS('All Data'!J31:J37-'All Data'!D31:D37)-$J8*'All Data'!D31:D37)^2)/(($U8-1)*$V8^2))) -> 0.013108456 | L8: 1794.0507 | M8: =SUMPRODUCT(ABS('All Data'!K31:K37-'All Data'!F31:F37))/$W8 -> 0.067887321 | N8: =IF($U8<2,"N/A (n=1)",TINV(0.05,$U8-1)*SQRT($U8*SUMPRODUCT((ABS('All Data'!K31:K37-'All Data'!F31:F37)-$M8*'All Data'!F31:F37)^2)/(($U8-1)*$W8^2))) -> 0.02410714 | O8: Y | P8: Y | Q8: Closed System; Rechargeable | U8: =COUNT('All Data'!D31:D37) -> 7 | V8: =SUM('All Data'!D31:D37) -> 560 | W8: =SUM('All Data'!F31:F37) -> 1680
A9: 7 | B9: Fzzybar X20000 | C9: 530 | D9: 3 | E9: =C9*D9 -> 1590 | F9: 18 | G9: 120 | H9: 40 | I9: 490 | J9: =SUMPRODUCT(ABS('All Data'!J90:J94-'All Data'!D90:D94))/$V9 -> 0.075471698 | K9: =IF($U9<2,"N/A (n=1)",TINV(0.05,$U9-1)*SQRT($U9*SUMPRODUCT((ABS('All Data'!J90:J94-'All Data'!D90:D94)-$J9*'All Data'!D90:D94)^2)/(($U9-1)*$V9^2))) -> 0.12520717 | L9: 1582.4889 | M9: =SUMPRODUCT(ABS('All Data'!K90:K94-'All Data'!F90:F94))/$W9 -> 0.068616038 | N9: =IF($U9<2,"N/A (n=1)",TINV(0.05,$U9-1)*SQRT($U9*SUMPRODUCT((ABS('All Data'!K90:K94-'All Data'!F90:F94)-$M9*'All Data'!F90:F94)^2)/(($U9-1)*$W9^2))) -> 0.076269102 | O9: Y | P9: Y | Q9: Closed System; Rechargeable | U9: =COUNT('All Data'!D90:D94) -> 5 | V9: =SUM('All Data'!D90:D94) -> 530 | W9: =SUM('All Data'!F90:F94) -> 1590
A10: 8 | B10: Geek Bar Pulse | C10: 400 | D10: 3 | E10: 1200 | F10: 18 | G10: 120 | H10: 40 | I10: 403 | J10: =SUMPRODUCT(ABS('All Data'!J10:J14-'All Data'!D10:D14))/$V10 -> 0.0075 | K10: =IF($U10<2,"N/A (n=1)",TINV(0.05,$U10-1)*SQRT($U10*SUMPRODUCT((ABS('All Data'!J10:J14-'All Data'!D10:D14)-$J10*'All Data'!D10:D14)^2)/(($U10-1)*$V10^2))) -> 0.013882226 | L10: 1252.7102 | M10: =SUMPRODUCT(ABS('All Data'!K10:K14-'All Data'!F10:F14))/$W10 -> 0.043925167 | N10: =IF($U10<2,"N/A (n=1)",TINV(0.05,$U10-1)*SQRT($U10*SUMPRODUCT((ABS('All Data'!K10:K14-'All Data'!F10:F14)-$M10*'All Data'!F10:F14)^2)/(($U10-1)*$W10^2))) -> 0.0072025226 | O10: Y | P10: Y | Q10: Closed System; Rechargeable | U10: =COUNT('All Data'!D10:D14) -> 5 | V10: =SUM('All Data'!D10:D14) -> 400 | W10: =SUM('All Data'!F10:F14) -> 1200
A11: 9 | B11: Hyde IQ5000 | C11: 536 | D11: 3 | E11: =C11*D11 -> 1608 | F11: 18 | G11: 120 | H11: 40 | I11: 505 | J11: =SUMPRODUCT(ABS('All Data'!J96:J103-'All Data'!D96:D103))/$V11 -> 0.061567164 | K11: =IF($U11<2,"N/A (n=1)",TINV(0.05,$U11-1)*SQRT($U11*SUMPRODUCT((ABS('All Data'!J96:J103-'All Data'!D96:D103)-$J11*'All Data'!D96:D103)^2)/(($U11-1)*$V11^2))) -> 0.057005773 | L11: 1450.9639 | M11: =SUMPRODUCT(ABS('All Data'!K96:K103-'All Data'!F96:F103))/$W11 -> 0.11488688 | N11: =IF($U11<2,"N/A (n=1)",TINV(0.05,$U11-1)*SQRT($U11*SUMPRODUCT((ABS('All Data'!K96:K103-'All Data'!F96:F103)-$M11*'All Data'!F96:F103)^2)/(($U11-1)*$W11^2))) -> 0.07042989 | O11: Y | P11: Y | Q11: Closed System; Rechargeable | U11: =COUNT('All Data'!D96:D103) -> 8 | V11: =SUM('All Data'!D96:D103) -> 536 | W11: =SUM('All Data'!F96:F103) -> 1608
A12: 10 | B12: Hyde N-bar | C12: 240 | D12: 3 | E12: =C12*D12 -> 720 | F12: 18 | G12: 120 | H12: 40 | I12: 236 | J12: =SUMPRODUCT(ABS('All Data'!J105:J107-'All Data'!D105:D107))/$V12 -> 0.016666667 | K12: =IF($U12<2,"N/A (n=1)",TINV(0.05,$U12-1)*SQRT($U12*SUMPRODUCT((ABS('All Data'!J105:J107-'All Data'!D105:D107)-$J12*'All Data'!D105:D107)^2)/(($U12-1)*$V12^2))) -> 0.071710879 | L12: 762.3135 | M12: =SUMPRODUCT(ABS('All Data'!K105:K107-'All Data'!F105:F107))/$W12 -> 0.089564861 | N12: =IF($U12<2,"N/A (n=1)",TINV(0.05,$U12-1)*SQRT($U12*SUMPRODUCT((ABS('All Data'!K105:K107-'All Data'!F105:F107)-$M12*'All Data'!F105:F107)^2)/(($U12-1)*$W12^2))) -> 0.093785673 | O12: Y | P12: Y | Q12: Closed System; Rechargeable | U12: =COUNT('All Data'!D105:D107) -> 3 | V12: =SUM('All Data'!D105:D107) -> 240 | W12: =SUM('All Data'!F105:F107) -> 720
A13: 11 | B13: Hyde Rebel | C13: 275 | D13: 3 | E13: =C13*D13 -> 825 | F13: 18 | G13: 120 | H13: 40 | I13: 271 | J13: =SUMPRODUCT(ABS('All Data'!J109:J113-'All Data'!D109:D113))/$V13 -> 0.021818182 | K13: =IF($U13<2,"N/A (n=1)",TINV(0.05,$U13-1)*SQRT($U13*SUMPRODUCT((ABS('All Data'!J109:J113-'All Data'!D109:D113)-$J13*'All Data'!D109:D113)^2)/(($U13-1)*$V13^2))) -> 0.028596062 | L13: 855.3565 | M13: =SUMPRODUCT(ABS('All Data'!K109:K113-'All Data'!F109:F113))/$W13 -> 0.036795758 | N13: =IF($U13<2,"N/A (n=1)",TINV(0.05,$U13-1)*SQRT($U13*SUMPRODUCT((ABS('All Data'!K109:K113-'All Data'!F109:F113)-$M13*'All Data'!F109:F113)^2)/(($U13-1)*$W13^2))) -> 0.029677878 | O13: Y | P13: Y | Q13: Closed System; Rechargeable | U13: =COUNT('All Data'!D109:D113) -> 5 | V13: =SUM('All Data'!D109:D113) -> 275 | W13: =SUM('All Data'!F109:F113) -> 825
A14: 12 | B14: Juul | C14: 185 | D14: 3 | E14: 555 | F14: 18 | G14: 120 | H14: 40 | I14: 185 | J14: =SUMPRODUCT(ABS('All Data'!J54:J56-'All Data'!D54:D56))/$V14 -> 0 | K14: =IF($U14<2,"N/A (n=1)",TINV(0.05,$U14-1)*SQRT($U14*SUMPRODUCT((ABS('All Data'!J54:J56-'All Data'!D54:D56)-$J14*'All Data'!D54:D56)^2)/(($U14-1)*$V14^2))) -> 0 | L14: 550.9164 | M14: =SUMPRODUCT(ABS('All Data'!K54:K56-'All Data'!F54:F56))/$W14 -> 0.0073578378 | N14: =IF($U14<2,"N/A (n=1)",TINV(0.05,$U14-1)*SQRT($U14*SUMPRODUCT((ABS('All Data'!K54:K56-'All Data'!F54:F56)-$M14*'All Data'!F54:F56)^2)/(($U14-1)*$W14^2))) -> 0.017134967 | O14: N | P14: N | Q14: Pod; Non-refillable | U14: =COUNT('All Data'!D54:D56) -> 3 | V14: =SUM('All Data'!D54:D56) -> 185 | W14: =SUM('All Data'!F54:F56) -> 555
A15: 13 | B15: Kangvape Speedy Beast X | C15: 360 | D15: 3 | E15: =C15*D15 -> 1080 | F15: 18 | G15: 120 | H15: 40 | I15: 357 | J15: =SUMPRODUCT(ABS('All Data'!J115:J123-'All Data'!D115:D123))/$V15 -> 0.013888889 | K15: =IF($U15<2,"N/A (n=1)",TINV(0.05,$U15-1)*SQRT($U15*SUMPRODUCT((ABS('All Data'!J115:J123-'All Data'!D115:D123)-$J15*'All Data'!D115:D123)^2)/(($U15-1)*$V15^2))) -> 0.025622268 | L15: 1062.3376 | M15: =SUMPRODUCT(ABS('All Data'!K115:K123-'All Data'!F115:F123))/$W15 -> 0.033045926 | N15: =IF($U15<2,"N/A (n=1)",TINV(0.05,$U15-1)*SQRT($U15*SUMPRODUCT((ABS('All Data'!K115:K123-'All Data'!F115:F123)-$M15*'All Data'!F115:F123)^2)/(($U15-1)*$W15^2))) -> 0.03520624 | O15: Y | P15: N | Q15: Closed System; Rechargeable | U15: =COUNT('All Data'!D115:D123) -> 9 | V15: =SUM('All Data'!D115:D123) -> 360 | W15: =SUM('All Data'!F115:F123) -> 1080
A16: 14 | B16: Lost Angel Sphere 35K | C16: 480 | D16: 3 | E16: 1440 | F16: 18 | G16: 120 | H16: 40 | I16: 480 | J16: =SUMPRODUCT(ABS('All Data'!J47:J52-'All Data'!D47:D52))/$V16 -> 0 | K16: =IF($U16<2,"N/A (n=1)",TINV(0.05,$U16-1)*SQRT($U16*SUMPRODUCT((ABS('All Data'!J47:J52-'All Data'!D47:D52)-$J16*'All Data'!D47:D52)^2)/(($U16-1)*$V16^2))) -> 0 | L16: 1481.2303 | M16: =SUMPRODUCT(ABS('All Data'!K47:K52-'All Data'!F47:F52))/$W16 -> 0.028632153 | N16: =IF($U16<2,"N/A (n=1)",TINV(0.05,$U16-1)*SQRT($U16*SUMPRODUCT((ABS('All Data'!K47:K52-'All Data'!F47:F52)-$M16*'All Data'!F47:F52)^2)/(($U16-1)*$W16^2))) -> 0.0014821303 | O16: Y | P16: N | Q16: Closed System; Rechargable | U16: =COUNT('All Data'!D47:D52) -> 6 | V16: =SUM('All Data'!D47:D52) -> 480 | W16: =SUM('All Data'!F47:F52) -> 1440
A17: 15 | B17: Lost Mary MT15000 | C17: 455 | D17: 3 | E17: 1365 | F17: 18 | G17: 120 | H17: 40 | I17: 449 | J17: =SUMPRODUCT(ABS('All Data'!J24:J29-'All Data'!D24:D29))/$V17 -> 0.026373626 | K17: =IF($U17<2,"N/A (n=1)",TINV(0.05,$U17-1)*SQRT($U17*SUMPRODUCT((ABS('All Data'!J24:J29-'All Data'!D24:D29)-$J17*'All Data'!D24:D29)^2)/(($U17-1)*$V17^2))) -> 0.015610502 | L17: 1395.8214 | M17: =SUMPRODUCT(ABS('All Data'!K24:K29-'All Data'!F24:F29))/$W17 -> 0.025857582 | N17: =IF($U17<2,"N/A (n=1)",TINV(0.05,$U17-1)*SQRT($U17*SUMPRODUCT((ABS('All Data'!K24:K29-'All Data'!F24:F29)-$M17*'All Data'!F24:F29)^2)/(($U17-1)*$W17^2))) -> 0.021006455 | O17: Y | P17: Y | Q17: Closed System; Rechargeable | U17: =COUNT('All Data'!D24:D29) -> 6 | V17: =SUM('All Data'!D24:D29) -> 455 | W17: =SUM('All Data'!F24:F29) -> 1365
A18: 16 | B18: Mr Fog Aura | C18: 1049 | D18: 3 | E18: =C18*D18 -> 3147 | F18: 18 | G18: 120 | H18: 40 | I18: 1013 | J18: =SUMPRODUCT(ABS('All Data'!J125:J135-'All Data'!D125:D135))/$V18 -> 0.053384175 | K18: =IF($U18<2,"N/A (n=1)",TINV(0.05,$U18-1)*SQRT($U18*SUMPRODUCT((ABS('All Data'!J125:J135-'All Data'!D125:D135)-$J18*'All Data'!D125:D135)^2)/(($U18-1)*$V18^2))) -> 0.067445933 | L18: 3210.8442 | M18: =SUMPRODUCT(ABS('All Data'!K125:K135-'All Data'!F125:F135))/$W18 -> 0.10805682 | N18: =IF($U18<2,"N/A (n=1)",TINV(0.05,$U18-1)*SQRT($U18*SUMPRODUCT((ABS('All Data'!K125:K135-'All Data'!F125:F135)-$M18*'All Data'!F125:F135)^2)/(($U18-1)*$W18^2))) -> 0.065920391 | O18: Y | P18: Y | Q18: Closed System; Rechargeable | U18: =COUNT('All Data'!D125:D135) -> 11 | V18: =SUM('All Data'!D125:D135) -> 1049 | W18: =SUM('All Data'!F125:F135) -> 3147
A19: 17 | B19: MR Fog Nova | C19: 1000 | D19: 3 | E19: =C19*D19 -> 3000 | F19: 18 | G19: 120 | H19: 40 | I19: 1004 | J19: =SUMPRODUCT(ABS('All Data'!J137:J161-'All Data'!D137:D161))/$V19 -> 0.006 | K19: =IF($U19<2,"N/A (n=1)",TINV(0.05,$U19-1)*SQRT($U19*SUMPRODUCT((ABS('All Data'!J137:J161-'All Data'!D137:D161)-$J19*'All Data'!D137:D161)^2)/(($U19-1)*$V19^2))) -> 0.005395164 | L19: 3249.2353 | M19: =SUMPRODUCT(ABS('All Data'!K137:K161-'All Data'!F137:F161))/$W19 -> 0.083078433 | N19: =IF($U19<2,"N/A (n=1)",TINV(0.05,$U19-1)*SQRT($U19*SUMPRODUCT((ABS('All Data'!K137:K161-'All Data'!F137:F161)-$M19*'All Data'!F137:F161)^2)/(($U19-1)*$W19^2))) -> 0.0081238309 | O19: Y | P19: Y | Q19: Closed System; Rechargeable | U19: =COUNT('All Data'!D137:D161) -> 25 | V19: =SUM('All Data'!D137:D161) -> 1000 | W19: =SUM('All Data'!F137:F161) -> 3000
A20: 18 | B20: Njoy Ace | C20: 80 | D20: 3 | E20: 240 | F20: 18 | G20: 120 | H20: 40 | I20: 80 | J20: =SUMPRODUCT(ABS('All Data'!J58:J58-'All Data'!D58:D58))/$V20 -> 0 | K20: =IF($U20<2,"N/A (n=1)",TINV(0.05,$U20-1)*SQRT($U20*SUMPRODUCT((ABS('All Data'!J58:J58-'All Data'!D58:D58)-$J20*'All Data'!D58:D58)^2)/(($U20-1)*$V20^2))) -> N/A (n=1) | L20: 285.3583 | M20: =SUMPRODUCT(ABS('All Data'!K58:K58-'All Data'!F58:F58))/$W20 -> 0.18899292 | N20: =IF($U20<2,"N/A (n=1)",TINV(0.05,$U20-1)*SQRT($U20*SUMPRODUCT((ABS('All Data'!K58:K58-'All Data'!F58:F58)-$M20*'All Data'!F58:F58)^2)/(($U20-1)*$W20^2))) -> N/A (n=1) | O20: N | P20: N | Q20: Pod; Non-refillable | U20: =COUNT('All Data'!D58:D58) -> 1 | V20: =SUM('All Data'!D58:D58) -> 80 | W20: =SUM('All Data'!F58:F58) -> 240
A21: 19 | B21: North 5000 Disposable | C21: 240 | D21: 3 | E21: =C21*D21 -> 720 | F21: 18 | G21: 120 | H21: 40 | I21: 240 | J21: =SUMPRODUCT(ABS('All Data'!J163:J168-'All Data'!D163:D168))/$V21 -> 0 | K21: =IF($U21<2,"N/A (n=1)",TINV(0.05,$U21-1)*SQRT($U21*SUMPRODUCT((ABS('All Data'!J163:J168-'All Data'!D163:D168)-$J21*'All Data'!D163:D168)^2)/(($U21-1)*$V21^2))) -> 0 | L21: 772.4195 | M21: =SUMPRODUCT(ABS('All Data'!K163:K168-'All Data'!F163:F168))/$W21 -> 0.072804861 | N21: =IF($U21<2,"N/A (n=1)",TINV(0.05,$U21-1)*SQRT($U21*SUMPRODUCT((ABS('All Data'!K163:K168-'All Data'!F163:F168)-$M21*'All Data'!F163:F168)^2)/(($U21-1)*$W21^2))) -> 0.0068526076 | O21: Y | P21: N | Q21: Closed System; Rechargeable | U21: =COUNT('All Data'!D163:D168) -> 6 | V21: =SUM('All Data'!D163:D168) -> 240 | W21: =SUM('All Data'!F163:F168) -> 720
A22: 20 | B22: Offstamp SW 9000 | C22: 600 | D22: 3 | E22: =C22*D22 -> 1800 | F22: 18 | G22: 120 | H22: 40 | I22: 604 | J22: =SUMPRODUCT(ABS('All Data'!J170:J184-'All Data'!D170:D184))/$V22 -> 0.0066666667 | K22: =IF($U22<2,"N/A (n=1)",TINV(0.05,$U22-1)*SQRT($U22*SUMPRODUCT((ABS('All Data'!J170:J184-'All Data'!D170:D184)-$J22*'All Data'!D170:D184)^2)/(($U22-1)*$V22^2))) -> 0.0082183512 | L22: 1952.5325 | M22: =SUMPRODUCT(ABS('All Data'!K170:K184-'All Data'!F170:F184))/$W22 -> 0.084740278 | N22: =IF($U22<2,"N/A (n=1)",TINV(0.05,$U22-1)*SQRT($U22*SUMPRODUCT((ABS('All Data'!K170:K184-'All Data'!F170:F184)-$M22*'All Data'!F170:F184)^2)/(($U22-1)*$W22^2))) -> 0.0090885021 | O22: Y | P22: Y | Q22: Pod; Non-refillable | U22: =COUNT('All Data'!D170:D184) -> 15 | V22: =SUM('All Data'!D170:D184) -> 600 | W22: =SUM('All Data'!F170:F184) -> 1800
A23: 21 | B23: Offstamp X cube | C23: 330 | D23: 3 | E23: =C23*D23 -> 990 | F23: 18 | G23: 120 | H23: 40 | I23: 293 | J23: =SUMPRODUCT(ABS('All Data'!J237:J242-'All Data'!D237:D242))/$V23 -> 0.11212121 | K23: =IF($U23<2,"N/A (n=1)",TINV(0.05,$U23-1)*SQRT($U23*SUMPRODUCT((ABS('All Data'!J237:J242-'All Data'!D237:D242)-$J23*'All Data'!D237:D242)^2)/(($U23-1)*$V23^2))) -> 0.089934399 | L23: 880.5201 | M23: =SUMPRODUCT(ABS('All Data'!K237:K242-'All Data'!F237:F242))/$W23 -> 0.14655081 | N23: =IF($U23<2,"N/A (n=1)",TINV(0.05,$U23-1)*SQRT($U23*SUMPRODUCT((ABS('All Data'!K237:K242-'All Data'!F237:F242)-$M23*'All Data'!F237:F242)^2)/(($U23-1)*$W23^2))) -> 0.079106757 | O23: Y | P23: Y | Q23: Pod; Non-refillable | U23: =COUNT('All Data'!D237:D242) -> 6 | V23: =SUM('All Data'!D237:D242) -> 330 | W23: =SUM('All Data'!F237:F242) -> 990
A24: 22 | B24: RAZ DC25000 | C24: 502 | D24: 3 | E24: 1506 | F24: 18 | G24: 120 | H24: 40 | I24: 497 | J24: =SUMPRODUCT(ABS('All Data'!J16:J22-'All Data'!D16:D22))/$V24 -> 0.013944223 | K24: =IF($U24<2,"N/A (n=1)",TINV(0.05,$U24-1)*SQRT($U24*SUMPRODUCT((ABS('All Data'!J16:J22-'All Data'!D16:D22)-$J24*'All Data'!D16:D22)^2)/(($U24-1)*$V24^2))) -> 0.022914683 | L24: 1555.7735 | M24: =SUMPRODUCT(ABS('All Data'!K16:K22-'All Data'!F16:F22))/$W24 -> 0.039820784 | N24: =IF($U24<2,"N/A (n=1)",TINV(0.05,$U24-1)*SQRT($U24*SUMPRODUCT((ABS('All Data'!K16:K22-'All Data'!F16:F22)-$M24*'All Data'!F16:F22)^2)/(($U24-1)*$W24^2))) -> 0.011759567 | O24: Y | P24: Y | Q24: Closed System; Rechargeable | U24: =COUNT('All Data'!D16:D22) -> 7 | V24: =SUM('All Data'!D16:D22) -> 502 | W24: =SUM('All Data'!F16:F22) -> 1506
A25: 23 | B25: Tyson Heavyweight | C25: 600 | D25: 3 | E25: =C25*D25 -> 1800 | F25: 18 | G25: 120 | H25: 40 | I25: 601 | J25: =SUMPRODUCT(ABS('All Data'!J186:J200-'All Data'!D186:D200))/$V25 -> 0.011666667 | K25: =IF($U25<2,"N/A (n=1)",TINV(0.05,$U25-1)*SQRT($U25*SUMPRODUCT((ABS('All Data'!J186:J200-'All Data'!D186:D200)-$J25*'All Data'!D186:D200)^2)/(($U25-1)*$V25^2))) -> 0.007149289 | L25: 1951.3244 | M25: =SUMPRODUCT(ABS('All Data'!K186:K200-'All Data'!F186:F200))/$W25 -> 0.084069111 | N25: =IF($U25<2,"N/A (n=1)",TINV(0.05,$U25-1)*SQRT($U25*SUMPRODUCT((ABS('All Data'!K186:K200-'All Data'!F186:F200)-$M25*'All Data'!F186:F200)^2)/(($U25-1)*$W25^2))) -> 0.0093285836 | O25: Y | P25: Y | Q25: Closed System; Rechargeable | U25: =COUNT('All Data'!D186:D200) -> 15 | V25: =SUM('All Data'!D186:D200) -> 600 | W25: =SUM('All Data'!F186:F200) -> 1800
A26: 24 | B26: Viho TRX 50k | C26: 826 | D26: 3 | E26: =C26*D26 -> 2478 | F26: 18 | G26: 120 | H26: 40 | I26: 818 | J26: =SUMPRODUCT(ABS('All Data'!J202:J209-'All Data'!D202:D209))/$V26 -> 0.00968523 | K26: =IF($U26<2,"N/A (n=1)",TINV(0.05,$U26-1)*SQRT($U26*SUMPRODUCT((ABS('All Data'!J202:J209-'All Data'!D202:D209)-$J26*'All Data'!D202:D209)^2)/(($U26-1)*$V26^2))) -> 0.01413583 | L26: 2636.1054 | M26: =SUMPRODUCT(ABS('All Data'!K202:K209-'All Data'!F202:F209))/$W26 -> 0.063803632 | N26: =IF($U26<2,"N/A (n=1)",TINV(0.05,$U26-1)*SQRT($U26*SUMPRODUCT((ABS('All Data'!K202:K209-'All Data'!F202:F209)-$M26*'All Data'!F202:F209)^2)/(($U26-1)*$W26^2))) -> 0.014843619 | O26: Y | P26: Y | Q26: Closed System; Rechargeable | U26: =COUNT('All Data'!D202:D209) -> 8 | V26: =SUM('All Data'!D202:D209) -> 826 | W26: =SUM('All Data'!F202:F209) -> 2478
A28: 27 | B28: Fogger Switch Pro | C28: 400 | D28: 3 | E28: =C28*D28 -> 1200 | F28: 18 | G28: 120 | H28: 40 | I28: 260 | J28: =SUMPRODUCT(ABS('All Data'!J214:J217-'All Data'!D214:D217))/$V28 -> 0.35 | K28: =IF($U28<2,"N/A (n=1)",TINV(0.05,$U28-1)*SQRT($U28*SUMPRODUCT((ABS('All Data'!J214:J217-'All Data'!D214:D217)-$J28*'All Data'!D214:D217)^2)/(($U28-1)*$V28^2))) -> 0.58508563 | L28: 797.3545 | M28: =SUMPRODUCT(ABS('All Data'!K214:K217-'All Data'!F214:F217))/$W28 -> 0.33553792 | N28: =IF($U28<2,"N/A (n=1)",TINV(0.05,$U28-1)*SQRT($U28*SUMPRODUCT((ABS('All Data'!K214:K217-'All Data'!F214:F217)-$M28*'All Data'!F214:F217)^2)/(($U28-1)*$W28^2))) -> 0.600073 | O28: Y | P28: Y | Q28: Pod; Non-refillable | U28: =COUNT('All Data'!D214:D217) -> 4 | V28: =SUM('All Data'!D214:D217) -> 400 | W28: =SUM('All Data'!F214:F217) -> 1200
A29: 28 | B29: Juul 2 | C29: 240 | D29: 3 | E29: =C29*D29 -> 720 | F29: 18 | G29: 120 | H29: 40 | I29: 1 | J29: =SUMPRODUCT(ABS('All Data'!J219:J221-'All Data'!D219:D221))/$V29 -> 0.99583333 | K29: =IF($U29<2,"N/A (n=1)",TINV(0.05,$U29-1)*SQRT($U29*SUMPRODUCT((ABS('All Data'!J219:J221-'All Data'!D219:D221)-$J29*'All Data'!D219:D221)^2)/(($U29-1)*$V29^2))) -> 0.01792772 | L29: 0.4032 | M29: =SUMPRODUCT(ABS('All Data'!K219:K221-'All Data'!F219:F221))/$W29 -> 0.99944 | N29: =IF($U29<2,"N/A (n=1)",TINV(0.05,$U29-1)*SQRT($U29*SUMPRODUCT((ABS('All Data'!K219:K221-'All Data'!F219:F221)-$M29*'All Data'!F219:F221)^2)/(($U29-1)*$W29^2))) -> 0.0024094855 | O29: N | P29: N | Q29: Pod; Non-refillable | U29: =COUNT('All Data'!D219:D221) -> 3 | V29: =SUM('All Data'!D219:D221) -> 240 | W29: =SUM('All Data'!F219:F221) -> 720
A30: 29 | B30: KangerTech SUBOX | C30: 650 | D30: 3 | E30: =C30*D30 -> 1950 | F30: 18 | G30: 120 | H30: 40 | I30: 150 | J30: =SUMPRODUCT(ABS('All Data'!J223:J227-'All Data'!D223:D227))/$V30 -> 0.76923077 | K30: =IF($U30<2,"N/A (n=1)",TINV(0.05,$U30-1)*SQRT($U30*SUMPRODUCT((ABS('All Data'!J223:J227-'All Data'!D223:D227)-$J30*'All Data'!D223:D227)^2)/(($U30-1)*$V30^2))) -> 0.052789484 | L30: 385.3958 | M30: =SUMPRODUCT(ABS('All Data'!K223:K227-'All Data'!F223:F227))/$W30 -> 0.80236113 | N30: =IF($U30<2,"N/A (n=1)",TINV(0.05,$U30-1)*SQRT($U30*SUMPRODUCT((ABS('All Data'!K223:K227-'All Data'!F223:F227)-$M30*'All Data'!F223:F227)^2)/(($U30-1)*$W30^2))) -> 0.11525878 | O30: Y | P30: N | Q30: Closed System; Rechargeable | U30: =COUNT('All Data'!D223:D227) -> 5 | V30: =SUM('All Data'!D223:D227) -> 650 | W30: =SUM('All Data'!F223:F227) -> 1950
A31: 30 | B31: LostMary OS5000 | C31: 560 | D31: 3 | E31: =C31*D31 -> 1680 | F31: 18 | G31: 120 | H31: 40 | I31: 326 | J31: =SUMPRODUCT(ABS('All Data'!J229:J235-'All Data'!D229:D235))/$V31 -> 0.41785714 | K31: =IF($U31<2,"N/A (n=1)",TINV(0.05,$U31-1)*SQRT($U31*SUMPRODUCT((ABS('All Data'!J229:J235-'All Data'!D229:D235)-$J31*'All Data'!D229:D235)^2)/(($U31-1)*$V31^2))) -> 0.157645 | L31: 788.0675 | M31: =SUMPRODUCT(ABS('All Data'!K229:K235-'All Data'!F229:F235))/$W31 -> 0.5309122 | N31: =IF($U31<2,"N/A (n=1)",TINV(0.05,$U31-1)*SQRT($U31*SUMPRODUCT((ABS('All Data'!K229:K235-'All Data'!F229:F235)-$M31*'All Data'!F229:F235)^2)/(($U31-1)*$W31^2))) -> 0.22340563 | O31: Y | P31: N | Q31: Closed System; Rechargeable | U31: =COUNT('All Data'!D229:D235) -> 7 | V31: =SUM('All Data'!D229:D235) -> 560 | W31: =SUM('All Data'!F229:F235) -> 1680

Sheet CI Method
A1: Confidence intervals for FRIENDS accuracy: method comparison
A2: puff-weighted ratio estimator with sessions as clusters (current Data Summary K/N).
A4: Vape | B4: n sessions | C4: Σ puffs delivered | D4: Min session size | E4: Max session size | F4: count WMAPE | G4: ±95% CI | H4: Signed count bias | I4: Signed ±95% CI | J4: time WMAPE | K4: ±95% CI | L4: Signed time bias | M4: Signed ±95% CI
A5: ='Data Summary'!B3 -> Adjust Myflavor | B5: ='Data Summary'!U3 -> 11 | C5: ='Data Summary'!V3 -> 440 | D5: =MIN('All Data'!D64:D74) -> 40 | E5: =MAX('All Data'!D64:D74) -> 40 | F5: ='Data Summary'!J3 -> 0 | G5: ='Data Summary'!K3 -> 0 | H5: =(SUM('All Data'!J64:J74)-SUM('All Data'!D64:D74))/SUM('All Data'!D64:D74) -> 0 | I5: =IF($B5<2,"N/A",TINV(0.05,$B5-1)*SQRT($B5*SUMPRODUCT((('All Data'!J64:J74-'All Data'!D64:D74)-H5*'All Data'!D64:D74)^2)/(($B5-1)*SUM('All Data'!D64:D74)^2))) -> 0 | J5: ='Data Summary'!M3 -> 0.089101818 | K5: ='Data Summary'!N3 -> 0.0055238047 | L5: =(SUM('All Data'!K64:K74)-SUM('All Data'!F64:F74))/SUM('All Data'!F64:F74) -> 0.089101818 | M5: =IF($B5<2,"N/A",TINV(0.05,$B5-1)*SQRT($B5*SUMPRODUCT((('All Data'!K64:K74-'All Data'!F64:F74)-L5*'All Data'!F64:F74)^2)/(($B5-1)*SUM('All Data'!F64:F74)^2))) -> 0.0055238047
A6: ='Data Summary'!B4 -> Artery CL6 | B6: ='Data Summary'!U4 -> 7 | C6: ='Data Summary'!V4 -> 433 | D6: =MIN('All Data'!D76:D82) -> 16 | E6: =MAX('All Data'!D76:D82) -> 140 | F6: ='Data Summary'!J4 -> 0.069284065 | G6: ='Data Summary'!K4 -> 0.099512295 | H6: =(SUM('All Data'!J76:J82)-SUM('All Data'!D76:D82))/SUM('All Data'!D76:D82) -> -0.069284065 | I6: =IF($B6<2,"N/A",TINV(0.05,$B6-1)*SQRT($B6*SUMPRODUCT((('All Data'!J76:J82-'All Data'!D76:D82)-H6*'All Data'!D76:D82)^2)/(($B6-1)*SUM('All Data'!D76:D82)^2))) -> 0.099512295 | J6: ='Data Summary'!M4 -> 0.091963048 | K6: ='Data Summary'!N4 -> 0.10106322 | L6: =(SUM('All Data'!K76:K82)-SUM('All Data'!F76:F82))/SUM('All Data'!F76:F82) -> 0.0097361047 | M6: =IF($B6<2,"N/A",TINV(0.05,$B6-1)*SQRT($B6*SUMPRODUCT((('All Data'!K76:K82-'All Data'!F76:F82)-L6*'All Data'!F76:F82)^2)/(($B6-1)*SUM('All Data'!F76:F82)^2))) -> 0.11263058
A7: ='Data Summary'!B5 -> Breeze Pro | B7: ='Data Summary'!U5 -> 5 | C7: ='Data Summary'!V5 -> 400 | D7: =MIN('All Data'!D39:D43) -> 80 | E7: =MAX('All Data'!D39:D43) -> 80 | F7: ='Data Summary'!J5 -> 0.0075 | G7: ='Data Summary'!K5 -> 0.020823338 | H7: =(SUM('All Data'!J39:J43)-SUM('All Data'!D39:D43))/SUM('All Data'!D39:D43) -> -0.0075 | I7: =IF($B7<2,"N/A",TINV(0.05,$B7-1)*SQRT($B7*SUMPRODUCT((('All Data'!J39:J43-'All Data'!D39:D43)-H7*'All Data'!D39:D43)^2)/(($B7-1)*SUM('All Data'!D39:D43)^2))) -> 0.020823338 | J7: ='Data Summary'!M5 -> 0.034191917 | K7: ='Data Summary'!N5 -> 0.013734479 | L7: =(SUM('All Data'!K39:K43)-SUM('All Data'!F39:F43))/SUM('All Data'!F39:F43) -> 0.034191917 | M7: =IF($B7<2,"N/A",TINV(0.05,$B7-1)*SQRT($B7*SUMPRODUCT((('All Data'!K39:K43-'All Data'!F39:F43)-L7*'All Data'!F39:F43)^2)/(($B7-1)*SUM('All Data'!F39:F43)^2))) -> 0.013734479
A8: ='Data Summary'!B6 -> EBCreate BC 5000 | B8: ='Data Summary'!U6 -> 5 | C8: ='Data Summary'!V6 -> 450 | D8: =MIN('All Data'!D84:D88) -> 70 | E8: =MAX('All Data'!D84:D88) -> 100 | F8: ='Data Summary'!J6 -> 0.0088888889 | G8: ='Data Summary'!K6 -> 0.013041524 | H8: =(SUM('All Data'!J84:J88)-SUM('All Data'!D84:D88))/SUM('All Data'!D84:D88) -> -0.0088888889 | I8: =IF($B8<2,"N/A",TINV(0.05,$B8-1)*SQRT($B8*SUMPRODUCT((('All Data'!J84:J88-'All Data'!D84:D88)-H8*'All Data'!D84:D88)^2)/(($B8-1)*SUM('All Data'!D84:D88)^2))) -> 0.013041524 | J8: ='Data Summary'!M6 -> 0.012941111 | K8: ='Data Summary'!N6 -> 0.0080553114 | L8: =(SUM('All Data'!K84:K88)-SUM('All Data'!F84:F88))/SUM('All Data'!F84:F88) -> 0.0061477778 | M8: =IF($B8<2,"N/A",TINV(0.05,$B8-1)*SQRT($B8*SUMPRODUCT((('All Data'!K84:K88-'All Data'!F84:F88)-L8*'All Data'!F84:F88)^2)/(($B8-1)*SUM('All Data'!F84:F88)^2))) -> 0.016661811
A9: ='Data Summary'!B7 -> Elf Bar BC5000 | B9: ='Data Summary'!U7 -> 6 | C9: ='Data Summary'!V7 -> 448 | D9: =MIN('All Data'!D3:D8) -> 48 | E9: =MAX('All Data'!D3:D8) -> 80 | F9: ='Data Summary'!J7 -> 0 | G9: ='Data Summary'!K7 -> 0 | H9: =(SUM('All Data'!J3:J8)-SUM('All Data'!D3:D8))/SUM('All Data'!D3:D8) -> 0 | I9: =IF($B9<2,"N/A",TINV(0.05,$B9-1)*SQRT($B9*SUMPRODUCT((('All Data'!J3:J8-'All Data'!D3:D8)-H9*'All Data'!D3:D8)^2)/(($B9-1)*SUM('All Data'!D3:D8)^2))) -> 0 | J9: ='Data Summary'!M7 -> 0.028843229 | K9: ='Data Summary'!N7 -> 0.015849925 | L9: =(SUM('All Data'!K3:K8)-SUM('All Data'!F3:F8))/SUM('All Data'!F3:F8) -> 0.026977753 | M9: =IF($B9<2,"N/A",TINV(0.05,$B9-1)*SQRT($B9*SUMPRODUCT((('All Data'!K3:K8-'All Data'!F3:F8)-L9*'All Data'!F3:F8)^2)/(($B9-1)*SUM('All Data'!F3:F8)^2))) -> 0.019918304
A10: ='Data Summary'!B8 -> Funky Republic ti7000 | B10: ='Data Summary'!U8 -> 7 | C10: ='Data Summary'!V8 -> 560 | D10: =MIN('All Data'!D31:D37) -> 80 | E10: =MAX('All Data'!D31:D37) -> 80 | F10: ='Data Summary'!J8 -> 0.0071428571 | G10: ='Data Summary'!K8 -> 0.013108456 | H10: =(SUM('All Data'!J31:J37)-SUM('All Data'!D31:D37))/SUM('All Data'!D31:D37) -> -0.0035714286 | I10: =IF($B10<2,"N/A",TINV(0.05,$B10-1)*SQRT($B10*SUMPRODUCT((('All Data'!J31:J37-'All Data'!D31:D37)-H10*'All Data'!D31:D37)^2)/(($B10-1)*SUM('All Data'!D31:D37)^2))) -> 0.014491944 | J10: ='Data Summary'!M8 -> 0.067887321 | K10: ='Data Summary'!N8 -> 0.02410714 | L10: =(SUM('All Data'!K31:K37)-SUM('All Data'!F31:F37))/SUM('All Data'!F31:F37) -> 0.067887321 | M10: =IF($B10<2,"N/A",TINV(0.05,$B10-1)*SQRT($B10*SUMPRODUCT((('All Data'!K31:K37-'All Data'!F31:F37)-L10*'All Data'!F31:F37)^2)/(($B10-1)*SUM('All Data'!F31:F37)^2))) -> 0.02410714
A11: ='Data Summary'!B9 -> Fzzybar X20000 | B11: ='Data Summary'!U9 -> 5 | C11: ='Data Summary'!V9 -> 530 | D11: =MIN('All Data'!D90:D94) -> 30 | E11: =MAX('All Data'!D90:D94) -> 140 | F11: ='Data Summary'!J9 -> 0.075471698 | G11: ='Data Summary'!K9 -> 0.12520717 | H11: =(SUM('All Data'!J90:J94)-SUM('All Data'!D90:D94))/SUM('All Data'!D90:D94) -> -0.075471698 | I11: =IF($B11<2,"N/A",TINV(0.05,$B11-1)*SQRT($B11*SUMPRODUCT((('All Data'!J90:J94-'All Data'!D90:D94)-H11*'All Data'!D90:D94)^2)/(($B11-1)*SUM('All Data'!D90:D94)^2))) -> 0.12520717 | J11: ='Data Summary'!M9 -> 0.068616038 | K11: ='Data Summary'!N9 -> 0.076269102 | L11: =(SUM('All Data'!K90:K94)-SUM('All Data'!F90:F94))/SUM('All Data'!F90:F94) -> -0.0047239623 | M11: =IF($B11<2,"N/A",TINV(0.05,$B11-1)*SQRT($B11*SUMPRODUCT((('All Data'!K90:K94-'All Data'!F90:F94)-L11*'All Data'!F90:F94)^2)/(($B11-1)*SUM('All Data'!F90:F94)^2))) -> 0.129706
A12: ='Data Summary'!B10 -> Geek Bar Pulse | B12: ='Data Summary'!U10 -> 5 | C12: ='Data Summary'!V10 -> 400 | D12: =MIN('All Data'!D10:D14) -> 80 | E12: =MAX('All Data'!D10:D14) -> 80 | F12: ='Data Summary'!J10 -> 0.0075 | G12: ='Data Summary'!K10 -> 0.013882226 | H12: =(SUM('All Data'!J10:J14)-SUM('All Data'!D10:D14))/SUM('All Data'!D10:D14) -> 0.0075 | I12: =IF($B12<2,"N/A",TINV(0.05,$B12-1)*SQRT($B12*SUMPRODUCT((('All Data'!J10:J14-'All Data'!D10:D14)-H12*'All Data'!D10:D14)^2)/(($B12-1)*SUM('All Data'!D10:D14)^2))) -> 0.013882226 | J12: ='Data Summary'!M10 -> 0.043925167 | K12: ='Data Summary'!N10 -> 0.0072025226 | L12: =(SUM('All Data'!K10:K14)-SUM('All Data'!F10:F14))/SUM('All Data'!F10:F14) -> 0.043925167 | M12: =IF($B12<2,"N/A",TINV(0.05,$B12-1)*SQRT($B12*SUMPRODUCT((('All Data'!K10:K14-'All Data'!F10:F14)-L12*'All Data'!F10:F14)^2)/(($B12-1)*SUM('All Data'!F10:F14)^2))) -> 0.0072025226
A13: ='Data Summary'!B11 -> Hyde IQ5000 | B13: ='Data Summary'!U11 -> 8 | C13: ='Data Summary'!V11 -> 536 | D13: =MIN('All Data'!D96:D103) -> 16 | E13: =MAX('All Data'!D96:D103) -> 80 | F13: ='Data Summary'!J11 -> 0.061567164 | G13: ='Data Summary'!K11 -> 0.057005773 | H13: =(SUM('All Data'!J96:J103)-SUM('All Data'!D96:D103))/SUM('All Data'!D96:D103) -> -0.057835821 | I13: =IF($B13<2,"N/A",TINV(0.05,$B13-1)*SQRT($B13*SUMPRODUCT((('All Data'!J96:J103-'All Data'!D96:D103)-H13*'All Data'!D96:D103)^2)/(($B13-1)*SUM('All Data'!D96:D103)^2))) -> 0.060594421 | J13: ='Data Summary'!M11 -> 0.11488688 | K13: ='Data Summary'!N11 -> 0.07042989 | L13: =(SUM('All Data'!K96:K103)-SUM('All Data'!F96:F103))/SUM('All Data'!F96:F103) -> -0.097659266 | M13: =IF($B13<2,"N/A",TINV(0.05,$B13-1)*SQRT($B13*SUMPRODUCT((('All Data'!K96:K103-'All Data'!F96:F103)-L13*'All Data'!F96:F103)^2)/(($B13-1)*SUM('All Data'!F96:F103)^2))) -> 0.090764043
A14: ='Data Summary'!B12 -> Hyde N-bar | B14: ='Data Summary'!U12 -> 3 | C14: ='Data Summary'!V12 -> 240 | D14: =MIN('All Data'!D105:D107) -> 80 | E14: =MAX('All Data'!D105:D107) -> 80 | F14: ='Data Summary'!J12 -> 0.016666667 | G14: ='Data Summary'!K12 -> 0.071710879 | H14: =(SUM('All Data'!J105:J107)-SUM('All Data'!D105:D107))/SUM('All Data'!D105:D107) -> -0.016666667 | I14: =IF($B14<2,"N/A",TINV(0.05,$B14-1)*SQRT($B14*SUMPRODUCT((('All Data'!J105:J107-'All Data'!D105:D107)-H14*'All Data'!D105:D107)^2)/(($B14-1)*SUM('All Data'!D105:D107)^2))) -> 0.071710879 | J14: ='Data Summary'!M12 -> 0.089564861 | K14: ='Data Summary'!N12 -> 0.093785673 | L14: =(SUM('All Data'!K105:K107)-SUM('All Data'!F105:F107))/SUM('All Data'!F105:F107) -> 0.05876875 | M14: =IF($B14<2,"N/A",TINV(0.05,$B14-1)*SQRT($B14*SUMPRODUCT((('All Data'!K105:K107-'All Data'!F105:F107)-L14*'All Data'!F105:F107)^2)/(($B14-1)*SUM('All Data'!F105:F107)^2))) -> 0.22600873
A15: ='Data Summary'!B13 -> Hyde Rebel | B15: ='Data Summary'!U13 -> 5 | C15: ='Data Summary'!V13 -> 275 | D15: =MIN('All Data'!D109:D113) -> 35 | E15: =MAX('All Data'!D109:D113) -> 80 | F15: ='Data Summary'!J13 -> 0.021818182 | G15: ='Data Summary'!K13 -> 0.028596062 | H15: =(SUM('All Data'!J109:J113)-SUM('All Data'!D109:D113))/SUM('All Data'!D109:D113) -> -0.014545455 | I15: =IF($B15<2,"N/A",TINV(0.05,$B15-1)*SQRT($B15*SUMPRODUCT((('All Data'!J109:J113-'All Data'!D109:D113)-H15*'All Data'!D109:D113)^2)/(($B15-1)*SUM('All Data'!D109:D113)^2))) -> 0.03647968 | J15: ='Data Summary'!M13 -> 0.036795758 | K15: ='Data Summary'!N13 -> 0.029677878 | L15: =(SUM('All Data'!K109:K113)-SUM('All Data'!F109:F113))/SUM('All Data'!F109:F113) -> 0.036795758 | M15: =IF($B15<2,"N/A",TINV(0.05,$B15-1)*SQRT($B15*SUMPRODUCT((('All Data'!K109:K113-'All Data'!F109:F113)-L15*'All Data'!F109:F113)^2)/(($B15-1)*SUM('All Data'!F109:F113)^2))) -> 0.029677878
A16: ='Data Summary'!B14 -> Juul | B16: ='Data Summary'!U14 -> 3 | C16: ='Data Summary'!V14 -> 185 | D16: =MIN('All Data'!D54:D56) -> 25 | E16: =MAX('All Data'!D54:D56) -> 80 | F16: ='Data Summary'!J14 -> 0 | G16: ='Data Summary'!K14 -> 0 | H16: =(SUM('All Data'!J54:J56)-SUM('All Data'!D54:D56))/SUM('All Data'!D54:D56) -> 0 | I16: =IF($B16<2,"N/A",TINV(0.05,$B16-1)*SQRT($B16*SUMPRODUCT((('All Data'!J54:J56-'All Data'!D54:D56)-H16*'All Data'!D54:D56)^2)/(($B16-1)*SUM('All Data'!D54:D56)^2))) -> 0 | J16: ='Data Summary'!M14 -> 0.0073578378 | K16: ='Data Summary'!N14 -> 0.017134967 | L16: =(SUM('All Data'!K54:K56)-SUM('All Data'!F54:F56))/SUM('All Data'!F54:F56) -> -0.0073578378 | M16: =IF($B16<2,"N/A",TINV(0.05,$B16-1)*SQRT($B16*SUMPRODUCT((('All Data'!K54:K56-'All Data'!F54:F56)-L16*'All Data'!F54:F56)^2)/(($B16-1)*SUM('All Data'!F54:F56)^2))) -> 0.017134967
A17: ='Data Summary'!B15 -> Kangvape Speedy Beast X | B17: ='Data Summary'!U15 -> 9 | C17: ='Data Summary'!V15 -> 360 | D17: =MIN('All Data'!D115:D123) -> 40 | E17: =MAX('All Data'!D115:D123) -> 40 | F17: ='Data Summary'!J15 -> 0.013888889 | G17: ='Data Summary'!K15 -> 0.025622268 | H17: =(SUM('All Data'!J115:J123)-SUM('All Data'!D115:D123))/SUM('All Data'!D115:D123) -> -0.0083333333 | I17: =IF($B17<2,"N/A",TINV(0.05,$B17-1)*SQRT($B17*SUMPRODUCT((('All Data'!J115:J123-'All Data'!D115:D123)-H17*'All Data'!D115:D123)^2)/(($B17-1)*SUM('All Data'!D115:D123)^2))) -> 0.027176519 | J17: ='Data Summary'!M15 -> 0.033045926 | K17: ='Data Summary'!N15 -> 0.03520624 | L17: =(SUM('All Data'!K115:K123)-SUM('All Data'!F115:F123))/SUM('All Data'!F115:F123) -> -0.016354074 | M17: =IF($B17<2,"N/A",TINV(0.05,$B17-1)*SQRT($B17*SUMPRODUCT((('All Data'!K115:K123-'All Data'!F115:F123)-L17*'All Data'!F115:F123)^2)/(($B17-1)*SUM('All Data'!F115:F123)^2))) -> 0.042279802
A18: ='Data Summary'!B16 -> Lost Angel Sphere 35K | B18: ='Data Summary'!U16 -> 6 | C18: ='Data Summary'!V16 -> 480 | D18: =MIN('All Data'!D47:D52) -> 80 | E18: =MAX('All Data'!D47:D52) -> 80 | F18: ='Data Summary'!J16 -> 0 | G18: ='Data Summary'!K16 -> 0 | H18: =(SUM('All Data'!J47:J52)-SUM('All Data'!D47:D52))/SUM('All Data'!D47:D52) -> 0 | I18: =IF($B18<2,"N/A",TINV(0.05,$B18-1)*SQRT($B18*SUMPRODUCT((('All Data'!J47:J52-'All Data'!D47:D52)-H18*'All Data'!D47:D52)^2)/(($B18-1)*SUM('All Data'!D47:D52)^2))) -> 0 | J18: ='Data Summary'!M16 -> 0.028632153 | K18: ='Data Summary'!N16 -> 0.0014821303 | L18: =(SUM('All Data'!K47:K52)-SUM('All Data'!F47:F52))/SUM('All Data'!F47:F52) -> 0.028632153 | M18: =IF($B18<2,"N/A",TINV(0.05,$B18-1)*SQRT($B18*SUMPRODUCT((('All Data'!K47:K52-'All Data'!F47:F52)-L18*'All Data'!F47:F52)^2)/(($B18-1)*SUM('All Data'!F47:F52)^2))) -> 0.0014821303
A19: ='Data Summary'!B17 -> Lost Mary MT15000 | B19: ='Data Summary'!U17 -> 6 | C19: ='Data Summary'!V17 -> 455 | D19: =MIN('All Data'!D24:D29) -> 55 | E19: =MAX('All Data'!D24:D29) -> 80 | F19: ='Data Summary'!J17 -> 0.026373626 | G19: ='Data Summary'!K17 -> 0.015610502 | H19: =(SUM('All Data'!J24:J29)-SUM('All Data'!D24:D29))/SUM('All Data'!D24:D29) -> -0.013186813 | I19: =IF($B19<2,"N/A",TINV(0.05,$B19-1)*SQRT($B19*SUMPRODUCT((('All Data'!J24:J29-'All Data'!D24:D29)-H19*'All Data'!D24:D29)^2)/(($B19-1)*SUM('All Data'!D24:D29)^2))) -> 0.029102483 | J19: ='Data Summary'!M17 -> 0.025857582 | K19: ='Data Summary'!N17 -> 0.021006455 | L19: =(SUM('All Data'!K24:K29)-SUM('All Data'!F24:F29))/SUM('All Data'!F24:F29) -> 0.02257978 | M19: =IF($B19<2,"N/A",TINV(0.05,$B19-1)*SQRT($B19*SUMPRODUCT((('All Data'!K24:K29-'All Data'!F24:F29)-L19*'All Data'!F24:F29)^2)/(($B19-1)*SUM('All Data'!F24:F29)^2))) -> 0.025457071
A20: ='Data Summary'!B18 -> Mr Fog Aura | B20: ='Data Summary'!U18 -> 11 | C20: ='Data Summary'!V18 -> 1049 | D20: =MIN('All Data'!D125:D135) -> 39 | E20: =MAX('All Data'!D125:D135) -> 200 | F20: ='Data Summary'!J18 -> 0.053384175 | G20: ='Data Summary'!K18 -> 0.067445933 | H20: =(SUM('All Data'!J125:J135)-SUM('All Data'!D125:D135))/SUM('All Data'!D125:D135) -> -0.034318398 | I20: =IF($B20<2,"N/A",TINV(0.05,$B20-1)*SQRT($B20*SUMPRODUCT((('All Data'!J125:J135-'All Data'!D125:D135)-H20*'All Data'!D125:D135)^2)/(($B20-1)*SUM('All Data'!D125:D135)^2))) -> 0.071324125 | J20: ='Data Summary'!M18 -> 0.10805682 | K20: ='Data Summary'!N18 -> 0.065920391 | L20: =(SUM('All Data'!K125:K135)-SUM('All Data'!F125:F135))/SUM('All Data'!F125:F135) -> 0.020287321 | M20: =IF($B20<2,"N/A",TINV(0.05,$B20-1)*SQRT($B20*SUMPRODUCT((('All Data'!K125:K135-'All Data'!F125:F135)-L20*'All Data'!F125:F135)^2)/(($B20-1)*SUM('All Data'!F125:F135)^2))) -> 0.087635799
A21: ='Data Summary'!B19 -> MR Fog Nova | B21: ='Data Summary'!U19 -> 25 | C21: ='Data Summary'!V19 -> 1000 | D21: =MIN('All Data'!D137:D161) -> 40 | E21: =MAX('All Data'!D137:D161) -> 40 | F21: ='Data Summary'!J19 -> 0.006 | G21: ='Data Summary'!K19 -> 0.005395164 | H21: =(SUM('All Data'!J137:J161)-SUM('All Data'!D137:D161))/SUM('All Data'!D137:D161) -> 0.004 | I21: =IF($B21<2,"N/A",TINV(0.05,$B21-1)*SQRT($B21*SUMPRODUCT((('All Data'!J137:J161-'All Data'!D137:D161)-H21*'All Data'!D137:D161)^2)/(($B21-1)*SUM('All Data'!D137:D161)^2))) -> 0.0057146763 | J21: ='Data Summary'!M19 -> 0.083078433 | K21: ='Data Summary'!N19 -> 0.0081238309 | L21: =(SUM('All Data'!K137:K161)-SUM('All Data'!F137:F161))/SUM('All Data'!F137:F161) -> 0.083078433 | M21: =IF($B21<2,"N/A",TINV(0.05,$B21-1)*SQRT($B21*SUMPRODUCT((('All Data'!K137:K161-'All Data'!F137:F161)-L21*'All Data'!F137:F161)^2)/(($B21-1)*SUM('All Data'!F137:F161)^2))) -> 0.0081238309
A22: ='Data Summary'!B20 -> Njoy Ace | B22: ='Data Summary'!U20 -> 1 | C22: ='Data Summary'!V20 -> 80 | D22: =MIN('All Data'!D58:D58) -> 80 | E22: =MAX('All Data'!D58:D58) -> 80 | F22: ='Data Summary'!J20 -> 0 | G22: ='Data Summary'!K20 -> N/A (n=1) | H22: =(SUM('All Data'!J58:J58)-SUM('All Data'!D58:D58))/SUM('All Data'!D58:D58) -> 0 | I22: =IF($B22<2,"N/A",TINV(0.05,$B22-1)*SQRT($B22*SUMPRODUCT((('All Data'!J58:J58-'All Data'!D58:D58)-H22*'All Data'!D58:D58)^2)/(($B22-1)*SUM('All Data'!D58:D58)^2))) -> N/A | J22: ='Data Summary'!M20 -> 0.18899292 | K22: ='Data Summary'!N20 -> N/A (n=1) | L22: =(SUM('All Data'!K58:K58)-SUM('All Data'!F58:F58))/SUM('All Data'!F58:F58) -> 0.18899292 | M22: =IF($B22<2,"N/A",TINV(0.05,$B22-1)*SQRT($B22*SUMPRODUCT((('All Data'!K58:K58-'All Data'!F58:F58)-L22*'All Data'!F58:F58)^2)/(($B22-1)*SUM('All Data'!F58:F58)^2))) -> N/A
A23: ='Data Summary'!B21 -> North 5000 Disposable | B23: ='Data Summary'!U21 -> 6 | C23: ='Data Summary'!V21 -> 240 | D23: =MIN('All Data'!D163:D168) -> 40 | E23: =MAX('All Data'!D163:D168) -> 40 | F23: ='Data Summary'!J21 -> 0 | G23: ='Data Summary'!K21 -> 0 | H23: =(SUM('All Data'!J163:J168)-SUM('All Data'!D163:D168))/SUM('All Data'!D163:D168) -> 0 | I23: =IF($B23<2,"N/A",TINV(0.05,$B23-1)*SQRT($B23*SUMPRODUCT((('All Data'!J163:J168-'All Data'!D163:D168)-H23*'All Data'!D163:D168)^2)/(($B23-1)*SUM('All Data'!D163:D168)^2))) -> 0 | J23: ='Data Summary'!M21 -> 0.072804861 | K23: ='Data Summary'!N21 -> 0.0068526076 | L23: =(SUM('All Data'!K163:K168)-SUM('All Data'!F163:F168))/SUM('All Data'!F163:F168) -> 0.072804861 | M23: =IF($B23<2,"N/A",TINV(0.05,$B23-1)*SQRT($B23*SUMPRODUCT((('All Data'!K163:K168-'All Data'!F163:F168)-L23*'All Data'!F163:F168)^2)/(($B23-1)*SUM('All Data'!F163:F168)^2))) -> 0.0068526076
A24: ='Data Summary'!B22 -> Offstamp SW 9000 | B24: ='Data Summary'!U22 -> 15 | C24: ='Data Summary'!V22 -> 600 | D24: =MIN('All Data'!D170:D184) -> 40 | E24: =MAX('All Data'!D170:D184) -> 40 | F24: ='Data Summary'!J22 -> 0.0066666667 | G24: ='Data Summary'!K22 -> 0.0082183512 | H24: =(SUM('All Data'!J170:J184)-SUM('All Data'!D170:D184))/SUM('All Data'!D170:D184) -> 0.0066666667 | I24: =IF($B24<2,"N/A",TINV(0.05,$B24-1)*SQRT($B24*SUMPRODUCT((('All Data'!J170:J184-'All Data'!D170:D184)-H24*'All Data'!D170:D184)^2)/(($B24-1)*SUM('All Data'!D170:D184)^2))) -> 0.0082183512 | J24: ='Data Summary'!M22 -> 0.084740278 | K24: ='Data Summary'!N22 -> 0.0090885021 | L24: =(SUM('All Data'!K170:K184)-SUM('All Data'!F170:F184))/SUM('All Data'!F170:F184) -> 0.084740278 | M24: =IF($B24<2,"N/A",TINV(0.05,$B24-1)*SQRT($B24*SUMPRODUCT((('All Data'!K170:K184-'All Data'!F170:F184)-L24*'All Data'!F170:F184)^2)/(($B24-1)*SUM('All Data'!F170:F184)^2))) -> 0.0090885021
A25: ='Data Summary'!B23 -> Offstamp X cube | B25: ='Data Summary'!U23 -> 6 | C25: ='Data Summary'!V23 -> 330 | D25: =MIN('All Data'!D237:D242) -> 40 | E25: =MAX('All Data'!D237:D242) -> 70 | F25: ='Data Summary'!J23 -> 0.11212121 | G25: ='Data Summary'!K23 -> 0.089934399 | H25: =(SUM('All Data'!J237:J242)-SUM('All Data'!D237:D242))/SUM('All Data'!D237:D242) -> -0.11212121 | I25: =IF($B25<2,"N/A",TINV(0.05,$B25-1)*SQRT($B25*SUMPRODUCT((('All Data'!J237:J242-'All Data'!D237:D242)-H25*'All Data'!D237:D242)^2)/(($B25-1)*SUM('All Data'!D237:D242)^2))) -> 0.089934399 | J25: ='Data Summary'!M23 -> 0.14655081 | K25: ='Data Summary'!N23 -> 0.079106757 | L25: =(SUM('All Data'!K237:K242)-SUM('All Data'!F237:F242))/SUM('All Data'!F237:F242) -> -0.11058576 | M25: =IF($B25<2,"N/A",TINV(0.05,$B25-1)*SQRT($B25*SUMPRODUCT((('All Data'!K237:K242-'All Data'!F237:F242)-L25*'All Data'!F237:F242)^2)/(($B25-1)*SUM('All Data'!F237:F242)^2))) -> 0.12702261
A26: ='Data Summary'!B24 -> RAZ DC25000 | B26: ='Data Summary'!U24 -> 7 | C26: ='Data Summary'!V24 -> 502 | D26: =MIN('All Data'!D16:D22) -> 22 | E26: =MAX('All Data'!D16:D22) -> 80 | F26: ='Data Summary'!J24 -> 0.013944223 | G26: ='Data Summary'!K24 -> 0.022914683 | H26: =(SUM('All Data'!J16:J22)-SUM('All Data'!D16:D22))/SUM('All Data'!D16:D22) -> -0.0099601594 | I26: =IF($B26<2,"N/A",TINV(0.05,$B26-1)*SQRT($B26*SUMPRODUCT((('All Data'!J16:J22-'All Data'!D16:D22)-H26*'All Data'!D16:D22)^2)/(($B26-1)*SUM('All Data'!D16:D22)^2))) -> 0.025188641 | J26: ='Data Summary'!M24 -> 0.039820784 | K26: ='Data Summary'!N24 -> 0.011759567 | L26: =(SUM('All Data'!K16:K22)-SUM('All Data'!F16:F22))/SUM('All Data'!F16:F22) -> 0.033050133 | M26: =IF($B26<2,"N/A",TINV(0.05,$B26-1)*SQRT($B26*SUMPRODUCT((('All Data'!K16:K22-'All Data'!F16:F22)-L26*'All Data'!F16:F22)^2)/(($B26-1)*SUM('All Data'!F16:F22)^2))) -> 0.026275427
A27: ='Data Summary'!B25 -> Tyson Heavyweight | B27: ='Data Summary'!U25 -> 15 | C27: ='Data Summary'!V25 -> 600 | D27: =MIN('All Data'!D186:D200) -> 40 | E27: =MAX('All Data'!D186:D200) -> 40 | F27: ='Data Summary'!J25 -> 0.011666667 | G27: ='Data Summary'!K25 -> 0.007149289 | H27: =(SUM('All Data'!J186:J200)-SUM('All Data'!D186:D200))/SUM('All Data'!D186:D200) -> 0.0016666667 | I27: =IF($B27<2,"N/A",TINV(0.05,$B27-1)*SQRT($B27*SUMPRODUCT((('All Data'!J186:J200-'All Data'!D186:D200)-H27*'All Data'!D186:D200)^2)/(($B27-1)*SUM('All Data'!D186:D200)^2))) -> 0.0097428386 | J27: ='Data Summary'!M25 -> 0.084069111 | K27: ='Data Summary'!N25 -> 0.0093285836 | L27: =(SUM('All Data'!K186:K200)-SUM('All Data'!F186:F200))/SUM('All Data'!F186:F200) -> 0.084069111 | M27: =IF($B27<2,"N/A",TINV(0.05,$B27-1)*SQRT($B27*SUMPRODUCT((('All Data'!K186:K200-'All Data'!F186:F200)-L27*'All Data'!F186:F200)^2)/(($B27-1)*SUM('All Data'!F186:F200)^2))) -> 0.0093285836
A28: ='Data Summary'!B26 -> Viho TRX 50k | B28: ='Data Summary'!U26 -> 8 | C28: ='Data Summary'!V26 -> 826 | D28: =MIN('All Data'!D202:D209) -> 40 | E28: =MAX('All Data'!D202:D209) -> 176 | F28: ='Data Summary'!J26 -> 0.00968523 | G28: ='Data Summary'!K26 -> 0.01413583 | H28: =(SUM('All Data'!J202:J209)-SUM('All Data'!D202:D209))/SUM('All Data'!D202:D209) -> -0.00968523 | I28: =IF($B28<2,"N/A",TINV(0.05,$B28-1)*SQRT($B28*SUMPRODUCT((('All Data'!J202:J209-'All Data'!D202:D209)-H28*'All Data'!D202:D209)^2)/(($B28-1)*SUM('All Data'!D202:D209)^2))) -> 0.01413583 | J28: ='Data Summary'!M26 -> 0.063803632 | K28: ='Data Summary'!N26 -> 0.014843619 | L28: =(SUM('All Data'!K202:K209)-SUM('All Data'!F202:F209))/SUM('All Data'!F202:F209) -> 0.063803632 | M28: =IF($B28<2,"N/A",TINV(0.05,$B28-1)*SQRT($B28*SUMPRODUCT((('All Data'!K202:K209-'All Data'!F202:F209)-L28*'All Data'!F202:F209)^2)/(($B28-1)*SUM('All Data'!F202:F209)^2))) -> 0.014843619
A29: ='Data Summary'!B28 -> Fogger Switch Pro | B29: ='Data Summary'!U28 -> 4 | C29: ='Data Summary'!V28 -> 400 | D29: =MIN('All Data'!D214:D217) -> 100 | E29: =MAX('All Data'!D214:D217) -> 100 | F29: ='Data Summary'!J28 -> 0.35 | G29: ='Data Summary'!K28 -> 0.58508563 | H29: =(SUM('All Data'!J214:J217)-SUM('All Data'!D214:D217))/SUM('All Data'!D214:D217) -> -0.35 | I29: =IF($B29<2,"N/A",TINV(0.05,$B29-1)*SQRT($B29*SUMPRODUCT((('All Data'!J214:J217-'All Data'!D214:D217)-H29*'All Data'!D214:D217)^2)/(($B29-1)*SUM('All Data'!D214:D217)^2))) -> 0.58508563 | J29: ='Data Summary'!M28 -> 0.33553792 | K29: ='Data Summary'!N28 -> 0.600073 | L29: =(SUM('All Data'!K214:K217)-SUM('All Data'!F214:F217))/SUM('All Data'!F214:F217) -> -0.33553792 | M29: =IF($B29<2,"N/A",TINV(0.05,$B29-1)*SQRT($B29*SUMPRODUCT((('All Data'!K214:K217-'All Data'!F214:F217)-L29*'All Data'!F214:F217)^2)/(($B29-1)*SUM('All Data'!F214:F217)^2))) -> 0.600073
A30: ='Data Summary'!B29 -> Juul 2 | B30: ='Data Summary'!U29 -> 3 | C30: ='Data Summary'!V29 -> 240 | D30: =MIN('All Data'!D219:D221) -> 80 | E30: =MAX('All Data'!D219:D221) -> 80 | F30: ='Data Summary'!J29 -> 0.99583333 | G30: ='Data Summary'!K29 -> 0.01792772 | H30: =(SUM('All Data'!J219:J221)-SUM('All Data'!D219:D221))/SUM('All Data'!D219:D221) -> -0.99583333 | I30: =IF($B30<2,"N/A",TINV(0.05,$B30-1)*SQRT($B30*SUMPRODUCT((('All Data'!J219:J221-'All Data'!D219:D221)-H30*'All Data'!D219:D221)^2)/(($B30-1)*SUM('All Data'!D219:D221)^2))) -> 0.01792772 | J30: ='Data Summary'!M29 -> 0.99944 | K30: ='Data Summary'!N29 -> 0.0024094855 | L30: =(SUM('All Data'!K219:K221)-SUM('All Data'!F219:F221))/SUM('All Data'!F219:F221) -> -0.99944 | M30: =IF($B30<2,"N/A",TINV(0.05,$B30-1)*SQRT($B30*SUMPRODUCT((('All Data'!K219:K221-'All Data'!F219:F221)-L30*'All Data'!F219:F221)^2)/(($B30-1)*SUM('All Data'!F219:F221)^2))) -> 0.0024094855
A31: ='Data Summary'!B30 -> KangerTech SUBOX | B31: ='Data Summary'!U30 -> 5 | C31: ='Data Summary'!V30 -> 650 | D31: =MIN('All Data'!D223:D227) -> 120 | E31: =MAX('All Data'!D223:D227) -> 140 | F31: ='Data Summary'!J30 -> 0.76923077 | G31: ='Data Summary'!K30 -> 0.052789484 | H31: =(SUM('All Data'!J223:J227)-SUM('All Data'!D223:D227))/SUM('All Data'!D223:D227) -> -0.76923077 | I31: =IF($B31<2,"N/A",TINV(0.05,$B31-1)*SQRT($B31*SUMPRODUCT((('All Data'!J223:J227-'All Data'!D223:D227)-H31*'All Data'!D223:D227)^2)/(($B31-1)*SUM('All Data'!D223:D227)^2))) -> 0.052789484 | J31: ='Data Summary'!M30 -> 0.80236113 | K31: ='Data Summary'!N30 -> 0.11525878 | L31: =(SUM('All Data'!K223:K227)-SUM('All Data'!F223:F227))/SUM('All Data'!F223:F227) -> -0.80236113 | M31: =IF($B31<2,"N/A",TINV(0.05,$B31-1)*SQRT($B31*SUMPRODUCT((('All Data'!K223:K227-'All Data'!F223:F227)-L31*'All Data'!F223:F227)^2)/(($B31-1)*SUM('All Data'!F223:F227)^2))) -> 0.11525878
A32: ='Data Summary'!B31 -> LostMary OS5000 | B32: ='Data Summary'!U31 -> 7 | C32: ='Data Summary'!V31 -> 560 | D32: =MIN('All Data'!D229:D235) -> 80 | E32: =MAX('All Data'!D229:D235) -> 80 | F32: ='Data Summary'!J31 -> 0.41785714 | G32: ='Data Summary'!K31 -> 0.157645 | H32: =(SUM('All Data'!J229:J235)-SUM('All Data'!D229:D235))/SUM('All Data'!D229:D235) -> -0.41785714 | I32: =IF($B32<2,"N/A",TINV(0.05,$B32-1)*SQRT($B32*SUMPRODUCT((('All Data'!J229:J235-'All Data'!D229:D235)-H32*'All Data'!D229:D235)^2)/(($B32-1)*SUM('All Data'!D229:D235)^2))) -> 0.157645 | J32: ='Data Summary'!M31 -> 0.5309122 | K32: ='Data Summary'!N31 -> 0.22340563 | L32: =(SUM('All Data'!K229:K235)-SUM('All Data'!F229:F235))/SUM('All Data'!F229:F235) -> -0.5309122 | M32: =IF($B32<2,"N/A",TINV(0.05,$B32-1)*SQRT($B32*SUMPRODUCT((('All Data'!K229:K235-'All Data'!F229:F235)-L32*'All Data'!F229:F235)^2)/(($B32-1)*SUM('All Data'!F229:F235)^2))) -> 0.22340563
A36: Method: Cochran ratio estimator, sessions as clusters
A37: For vape v with sessions j = 1..n: x_j = delivered puffs (or delivered puff time), u_j = |counted - delivered|.
A38: Point estimate R = Σ u_j / Σ x_j (puff-weighted mean absolute relative error, WMAPE)
A39: Variance v(R) = n * Σ (u_j - R*x_j)^2 / [ (n-1) * (Σ x_j)^2 ]
A40: 95% CI R ± t(0.975, n-1) * SQRT(v(R))
A41: This weights each session by its own size, makes no distributional assumption about within-session errors, and is robust to correlation of errors within a session. It is the standard survey-sampling variance for a ratio of totals (Cochran 1977, Sampling Techniques, 3rd ed., Sec. 6.3).
A43: Assumptions and limitations
A44: a) Sessions within a vape are treated as independent replicate clusters. If sessions were run back-to-back on one coil, this is optimistic (coil ageing induces between-session drift that is not exchangeable).
A45: b) n = 1 (Njoy Ace) admits no session-level variance estimate; K/N return "N/A (n=1)". A puff-level Wilson score interval on the detection rate (80/80 detected -> 95.4%-100%) is the only alternative, but see (c).
...

Sheet All Data
B2: Vape | C2: Puff Session | D2: Number of Puffs | E2: Actual Puff Time (s) | F2: Total Puff Time (s) | G2: Interpuff Time (s) | H2: Puff Volume (mL) | I2: Puff Flow Rate (mL/s) | J2: Puffs Counted | K2: Recorded Puff Time (s) | L2: Puff Count RE (per session) | M2: Puff Time RE (per session)
B3: Elf Bar BC5000 | C3: 1 | D3: 80 | E3: 3 | F3: =D3*E3 -> 240 | G3: 18 | H3: 120 | I3: 40 | J3: 80 | K3: 238.7464 | L3: =ABS((J3-D3)/D3) -> 0 | M3: =ABS((K3-F3)/F3) -> 0.0052233333
C4: 2 | D4: 80 | E4: 3 | F4: =D4*E4 -> 240 | G4: 18 | H4: 120 | I4: 40 | J4: 80 | K4: 244.4862 | L4: =ABS((J4-D4)/D4) -> 0 | M4: =ABS((K4-F4)/F4) -> 0.0186925
C5: 3 | D5: 80 | E5: 3 | F5: =D5*E5 -> 240 | G5: 18 | H5: 120 | I5: 40 | J5: 80 | K5: 250.0572 | L5: =ABS((J5-D5)/D5) -> 0 | M5: =ABS((K5-F5)/F5) -> 0.041905
C6: 4 | D6: 80 | E6: 3 | F6: =D6*E6 -> 240 | G6: 18 | H6: 120 | I6: 40 | J6: 80 | K6: 249.418 | L6: =ABS((J6-D6)/D6) -> 0 | M6: =ABS((K6-F6)/F6) -> 0.039241667
C7: 5 | D7: 80 | E7: 3 | F7: =D7*E7 -> 240 | G7: 18 | H7: 120 | I7: 40 | J7: 80 | K7: 248.3032 | L7: =ABS((J7-D7)/D7) -> 0 | M7: =ABS((K7-F7)/F7) -> 0.034596667
C8: 6 | D8: 48 | E8: 3 | F8: =D8*E8 -> 144 | G8: 18 | H8: 120 | I8: 40 | J8: 48 | K8: 149.2471 | L8: =ABS((J8-D8)/D8) -> 0 | M8: =ABS((K8-F8)/F8) -> 0.036438194
C9: Overall | D9: =SUM(D3:D8) -> 448 | E9: - | F9: =SUM(F3:F8) -> 1344 | G9: - | H9: - | I9: - | J9: =SUM(J3:J8) -> 448 | K9: =SUM(K3:K8) -> 1380.2581
B10: Geek Bar Pulse | C10: 1 | D10: 80 | E10: 3 | F10: =D10*E10 -> 240 | G10: 18 | H10: 120 | I10: 40 | J10: 80 | K10: 249.9346 | L10: =ABS((J10-D10)/D10) -> 0 | M10: =ABS((K10-F10)/F10) -> 0.041394167
C11: 2 | D11: 80 | E11: 3 | F11: =D11*E11 -> 240 | G11: 18 | H11: 120 | I11: 40 | J11: 82 | K11: 252.4966 | L11: =ABS((J11-D11)/D11) -> 0.025 | M11: =ABS((K11-F11)/F11) -> 0.052069167
C12: 3 | D12: 80 | E12: 3 | F12: =D12*E12 -> 240 | G12: 18 | H12: 120 | I12: 40 | J12: 81 | K12: 251.0437 | L12: =ABS((J12-D12)/D12) -> 0.0125 | M12: =ABS((K12-F12)/F12) -> 0.046015417
C13: 4 | D13: 80 | E13: 3 | F13: =D13*E13 -> 240 | G13: 18 | H13: 120 | I13: 40 | J13: 80 | K13: 250.5128 | L13: =ABS((J13-D13)/D13) -> 0 | M13: =ABS((K13-F13)/F13) -> 0.043803333
C14: 5 | D14: 80 | E14: 3 | F14: =D14*E14 -> 240 | G14: 18 | H14: 120 | I14: 40 | J14: 80 | K14: 248.7225 | L14: =ABS((J14-D14)/D14) -> 0 | M14: =ABS((K14-F14)/F14) -> 0.03634375
C15: Overall | D15: =SUM(D10:D14) -> 400 | E15: - | F15: =SUM(F10:F14) -> 1200 | G15: - | H15: - | I15: - | J15: =SUM(J10:J14) -> 403 | K15: =SUM(K10:K14) -> 1252.7102
B16: RAZ DC25000 | C16: 1 | D16: 80 | E16: 3 | F16: =D16*E16 -> 240 | G16: 18 | H16: 120 | I16: 40 | J16: 81 | K16: 253.9351 | L16: =ABS((J16-D16)/D16) -> 0.0125 | M16: =ABS((K16-F16)/F16) -> 0.058062917
C17: 2 | D17: 80 | E17: 3 | F17: =D17*E17 -> 240 | G17: 18 | H17: 120 | I17: 40 | J17: 80 | K17: 250.8108 | L17: =ABS((J17-D17)/D17) -> 0 | M17: =ABS((K17-F17)/F17) -> 0.045045
C18: 3 | D18: 80 | E18: 3 | F18: =D18*E18 -> 240 | G18: 18 | H18: 120 | I18: 40 | J18: 80 | K18: 250.3718 | L18: =ABS((J18-D18)/D18) -> 0 | M18: =ABS((K18-F18)/F18) -> 0.043215833
C19: 4 | D19: 80 | E19: 3 | F19: =D19*E19 -> 240 | G19: 18 | H19: 120 | I19: 40 | J19: 79 | K19: 247.8016 | L19: =ABS((J19-D19)/D19) -> 0.0125 | M19: =ABS((K19-F19)/F19) -> 0.032506667
C20: 5 | D20: 80 | E20: 3 | F20: =D20*E20 -> 240 | G20: 18 | H20: 120 | I20: 40 | J20: 80 | K20: 249.9447 | L20: =ABS((J20-D20)/D20) -> 0 | M20: =ABS((K20-F20)/F20) -> 0.04143625
C21: 6 | D21: 80 | E21: 3 | F21: 240 | G21: 18 | H21: 120 | I21: 40 | J21: 75 | K21: 234.9017 | L21: =ABS((J21-D21)/D21) -> 0.0625 | M21: =ABS((K21-F21)/F21) -> 0.021242917
C22: 7 | D22: 22 | E22: 3 | F22: =D22*E22 -> 66 | G22: 18 | H22: 120 | I22: 40 | J22: 22 | K22: 68.0078 | L22: =ABS((J22-D22)/D22) -> 0 | M22: =ABS((K22-F22)/F22) -> 0.030421212
C23: Overall | D23: =SUM(D16:D22) -> 502 | E23: - | F23: =SUM(F16:F22) -> 1506 | G23: - | H23: - | I23: - | J23: =SUM(J16:J22) -> 497 | K23: =SUM(K16:K22) -> 1555.7735
B24: Lost Mary MT15000 | C24: 1 | D24: 80 | E24: 3 | F24: =D24*E24 -> 240 | G24: 18 | H24: 120 | I24: 40 | J24: 79 | K24: 242.5057 | L24: =ABS((J24-D24)/D24) -> 0.0125 | M24: =ABS((K24-F24)/F24) -> 0.010440417
C25: 2 | D25: 80 | E25: 3 | F25: =D25*E25 -> 240 | G25: 18 | H25: 120 | I25: 40 | J25: 78 | K25: 244.0737 | L25: =ABS((J25-D25)/D25) -> 0.025 | M25: =ABS((K25-F25)/F25) -> 0.01697375
C26: 3 | D26: 80 | E26: 3 | F26: =D26*E26 -> 240 | G26: 18 | H26: 120 | I26: 40 | J26: 81 | K26: 250.9333 | L26: =ABS((J26-D26)/D26) -> 0.0125 | M26: =ABS((K26-F26)/F26) -> 0.045555417
C27: 4 | D27: 80 | E27: 3 | F27: =D27*E27 -> 240 | G27: 18 | H27: 120 | I27: 40 | J27: 76 | K27: 237.7629 | L27: =ABS((J27-D27)/D27) -> 0.05 | M27: =ABS((K27-F27)/F27) -> 0.00932125
C28: 5 | D28: 80 | E28: 3 | F28: =D28*E28 -> 240 | G28: 18 | H28: 120 | I28: 40 | J28: 78 | K28: 244.5904 | L28: =ABS((J28-D28)/D28) -> 0.025 | M28: =ABS((K28-F28)/F28) -> 0.019126667
C29: 6 | D29: 55 | E29: 3 | F29: =D29*E29 -> 165 | G29: 18 | H29: 120 | I29: 40 | J29: 57 | K29: 175.9554 | L29: =ABS((J29-D29)/D29) -> 0.036363636 | M29: =ABS((K29-F29)/F29) -> 0.066396364
C30: Overall | D30: =SUM(D24:D29) -> 455 | E30: - | F30: =SUM(F24:F29) -> 1365 | G30: - | H30: - | I30: - | J30: =SUM(J24:J29) -> 449 | K30: =SUM(K24:K29) -> 1395.8214
B31: Funky Republic ti7000 | C31: 1 | D31: 80 | E31: 3 | F31: =D31*E31 -> 240 | G31: 18 | H31: 120 | I31: 40 | J31: 80 | K31: 250.7872 | L31: =ABS((J31-D31)/D31) -> 0 | M31: =ABS((K31-F31)/F31) -> 0.044946667
C32: 2 | D32: 80 | E32: 3 | F32: =D32*E32 -> 240 | G32: 18 | H32: 120 | I32: 40 | J32: 80 | K32: 254.519 | L32: =ABS((J32-D32)/D32) -> 0 | M32: =ABS((K32-F32)/F32) -> 0.060495833
C33: 3 | D33: 80 | E33: 3 | F33: =D33*E33 -> 240 | G33: 18 | H33: 120 | I33: 40 | J33: 77 | K33: 245.8975 | L33: =ABS((J33-D33)/D33) -> 0.0375 | M33: =ABS((K33-F33)/F33) -> 0.024572917
C34: 4 | D34: 80 | E34: 3 | F34: =D34*E34 -> 240 | G34: 18 | H34: 120 | I34: 40 | J34: 81 | K34: 261.9976 | L34: =ABS((J34-D34)/D34) -> 0.0125 | M34: =ABS((K34-F34)/F34) -> 0.091656667
C35: 5 | D35: 80 | E35: 3 | F35: =D35*E35 -> 240 | G35: 18 | H35: 120 | I35: 40 | J35: 80 | K35: 261.9183 | L35: =ABS((J35-D35)/D35) -> 0 | M35: =ABS((K35-F35)/F35) -> 0.09132625
C36: 6 | D36: 80 | E36: 3 | F36: 240 | G36: 18 | H36: 120 | I36: 40 | J36: 80 | K36: 261.5835 | L36: =ABS((J36-D36)/D36) -> 0 | M36: =ABS((K36-F36)/F36) -> 0.08993125
C37: 7 | D37: 80 | E37: 3 | F37: =D37*E37 -> 240 | G37: 18 | H37: 120 | I37: 40 | J37: 80 | K37: 257.3476 | L37: =ABS((J37-D37)/D37) -> 0 | M37: =ABS((K37-F37)/F37) -> 0.072281667
C38: Overall | D38: =SUM(D31:D37) -> 560 | E38: - | F38: =SUM(F31:F37) -> 1680 | G38: - | H38: - | I38: - | J38: =SUM(J31:J37) -> 558 | K38: =SUM(K31:K37) -> 1794.0507
B39: Breeze Pro | C39: 1 | D39: 80 | E39: 3 | F39: =D39*E39 -> 240 | G39: 18 | H39: 120 | I39: 40 | J39: 80 | K39: 249.3192 | L39: =ABS((J39-D39)/D39) -> 0 | M39: =ABS((K39-F39)/F39) -> 0.03883
C40: 2 | D40: 80 | E40: 3 | F40: =D40*E40 -> 240 | G40: 18 | H40: 120 | I40: 40 | J40: 80 | K40: 248.4511 | L40: =ABS((J40-D40)/D40) -> 0 | M40: =ABS((K40-F40)/F40) -> 0.035212917
C41: 3 | D41: 80 | E41: 3 | F41: =D41*E41 -> 240 | G41: 18 | H41: 120 | I41: 40 | J41: 80 | K41: 249.44 | L41: =ABS((J41-D41)/D41) -> 0 | M41: =ABS((K41-F41)/F41) -> 0.039333333
...
